[2024-06-28T00:00:01.455+0000] {task_context_logger.py:104} ERROR - Executor reports task instance <TaskInstance: podcast_summary.get_episodes scheduled__2024-06-27T00:00:00+00:00 [queued]> finished (failed) although the task says it's queued. (Info: None) Was the task killed externally?
