[2024-06-13T21:13:27.724+0000] {task_context_logger.py:104} ERROR - Executor reports task instance <TaskInstance: podcast_summary.get_episodes manual__2024-06-13T21:13:26.056718+00:00 [queued]> finished (failed) although the task says it's queued. (Info: None) Was the task killed externally?
